<?xml version="1.0"?>
<robot name="robot" >
  <link name="link_chassis">
    <!-- pose and inertial -->
    <pose>0 0 0.07 0 0 0</pose>
    <inertial>
      <mass value="1"/>
      <origin rpy="0 0 0" xyz="0 0 0.07"/>
      <inertia ixx="0.0395416666667" ixy="0" ixz="0" iyy="0.106208333333" iyz="0" izz="0.106208333333"/>
    </inertial>
    <!-- body -->
    <collision name="collision_chassis">
      <geometry>
        <box size="0.2 0.15 0.03"/>
      </geometry>
    </collision>
    <visual>
      <origin rpy="0 0 0" xyz="0 0 0"/>
      <geometry>
        <box size="0.2 0.15 0.03"/>
      </geometry>
    </visual>
  </link>
  <!-- right wheel back-->
  <joint name="joint_right_wheel" type="continuous">
    <origin rpy="0 0 0" xyz="-0.07 0.1 -0.03"/>
    <child link="link_right_wheel"/>
    <parent link="link_chassis"/>
    <axis rpy="0 0 0" xyz="0 1 0"/>
    <limit effort="10000" velocity="1000"/>
    <joint_properties damping="0" friction="0"/>
  </joint>

  <link name="link_right_wheel">
    <inertial>
      <mass value="0.2"/>
      <origin rpy="0 1.5707 1.5707" xyz="0 0 0"/>
      <inertia ixx="0.000526666666667" ixy="0" ixz="0" iyy="0.000526666666667" iyz="0" izz="0.001"/>
    </inertial>
    <collision name="link_right_wheel_collision">
      <origin rpy="0 1.5707 1.5707" xyz="0 0 0"/>
      <geometry>
        <cylinder length="0.03" radius="0.04"/>
      </geometry>
    </collision>
    <visual name="link_right_wheel_visual">
      <origin rpy="0 1.5707 1.5707" xyz="0 0 0"/>
      <geometry>
        <cylinder length="0.03" radius="0.04"/>
      </geometry>
    </visual>
  </link>
  
  
  
  <!-- left wheel back-->
  <joint name="joint_left_wheel" type="continuous">
    <origin rpy="0 0 0" xyz="-0.07 -0.1 -0.03"/>
    <child link="link_left_wheel"/>
    <parent link="link_chassis"/>
    <axis rpy="0 0 0" xyz="0 1 0"/>
    <limit effort="10000" velocity="1000"/>
    <joint_properties damping="0" friction="0"/>
  </joint>

  <link name="link_left_wheel">
    <inertial>
      <mass value="0.2"/>
      <origin rpy="0 1.5707 1.5707" xyz="0 0 0"/>
      <inertia ixx="0.000526666666667" ixy="0" ixz="0" iyy="0.000526666666667" iyz="0" izz="0.001"/>
    </inertial>
    <collision name="link_left_wheel_collision">
      <origin rpy="0 1.5707 1.5707" xyz="0 0 0"/>
      <geometry>
        <cylinder length="0.03" radius="0.04"/>
      </geometry>
    </collision>
    <visual name="link_left_wheel_visual">
      <origin rpy="0 1.5707 1.5707" xyz="0 0 0"/>
      <geometry>
        <cylinder length="0.03" radius="0.04"/>
      </geometry>
    </visual>
  </link>
  
 
  <!-- right wheel front-->
  <joint name="joint_right_wheelf" type="continuous">
    <origin rpy="0 0 0" xyz="0.06 0.1 -0.03"/>
    <child link="link_right_wheelf"/>
    <parent link="link_chassis"/>
    <axis rpy="0 0 0" xyz="0 1 0"/>
    <limit effort="10000" velocity="1000"/>
    <joint_properties damping="0" friction="0"/>
  </joint>

  <link name="link_right_wheelf">
    <inertial>
      <mass value="0.2"/>
      <origin rpy="0 1.5707 1.5707" xyz="0 0 0"/>
      <inertia ixx="0.000526666666667" ixy="0" ixz="0" iyy="0.000526666666667" iyz="0" izz="0.001"/>
    </inertial>
    <collision name="link_right_wheelf_collision">
      <origin rpy="0 1.5707 1.5707" xyz="0 0 0"/>
      <geometry>
        <cylinder length="0.03" radius="0.04"/>
      </geometry>
    </collision>
    <visual name="link_right_wheelf_visual">
      <origin rpy="0 1.5707 1.5707" xyz="0 0 0"/>
      <geometry>
        <cylinder length="0.03" radius="0.04"/>
      </geometry>
    </visual>
  </link>
  
  <!-- left wheel front-->
  <joint name="joint_left_wheelf" type="continuous">
    <origin rpy="0 0 0" xyz="0.06 -0.1 -0.03"/>
    <child link="link_left_wheelf"/>
    <parent link="link_chassis"/>
    <axis rpy="0 0 0" xyz="0 1 0"/>
    <limit effort="10000" velocity="1000"/>
    <joint_properties damping="0" friction="0"/>
  </joint>

  <link name="link_left_wheelf">
    <inertial>
      <mass value="0.2"/>
      <origin rpy="0 1.5707 1.5707" xyz="0 0 0"/>
      <inertia ixx="0.000526666666667" ixy="0" ixz="0" iyy="0.000526666666667" iyz="0" izz="0.001"/>
    </inertial>
    <collision name="link_left_wheelf_collision">
      <origin rpy="0 1.5707 1.5707" xyz="0 0 0"/>
      <geometry>
        <cylinder length="0.03" radius="0.04"/>
      </geometry>
    </collision>
    <visual name="link_left_wheef_visual">
      <origin rpy="0 1.5707 1.5707" xyz="0 0 0"/>
      <geometry>
        <cylinder length="0.03" radius="0.04"/>
      </geometry>
    </visual>
  </link>
  

    <!-- laser sensor -->
       <link name="laser_sensor">
    <inertial>
      <mass value="0.01"/>
      <origin rpy="0 0 0" xyz="0 0 0"/>
      <inertia ixx="0.000526666666667" ixy="0" ixz="0" iyy="0.000526666666667" iyz="0" izz="0.001"/>
    </inertial>
    <collision name="laser_sensor_collision">
      <origin rpy=" 0 0 0" xyz="0.0 0 0.0"/>
      <geometry>
        <cylinder length="0.03" radius="0.04"/>
      </geometry>
    </collision>
    <visual name="laser_sensor_visual">
      <origin rpy=" 0 0 0" xyz="0.0 0 0.0"/>
      <geometry>
        <cylinder length="0.03" radius="0.04"/>
      </geometry>
    </visual>
  </link>
  
   <joint name="joint_laser_sensor" type="fixed">
    <origin rpy="0 0 0" xyz="0.05 0 0.03"/>
    <child link="laser_sensor"/>
    <parent link="link_chassis"/>
    <axis rpy="0 0 0" xyz="0 1 0"/>
    <limit effort="10000" velocity="1000"/>
    <joint_properties damping="0" friction="0"/>
  </joint>

<gazebo>
    <plugin name="differential_drive_controller" filename="libgazebo_ros_diff_drive.so">
     <alwaysOn>true</alwaysOn>
     <updateRate>10</updateRate>
     <legacyMode>true</legacyMode>
     <leftJoint>joint_left_wheel</leftJoint>
     <rightJoint>joint_right_wheel</rightJoint>
     <wheelSeparation>0.5380</wheelSeparation>
     <wheelDiameter>0.2410</wheelDiameter>
     <torque>20</torque>
     <commandTopic>cmd_vel</commandTopic>
     <odometryTopic>odom</odometryTopic>
     <odometryFrame>odom</odometryFrame>
     <robotBaseFrame>link_chassis</robotBaseFrame>
     <publishWheelTF>false</publishWheelTF>
     <publishWheelJointState>false</publishWheelJointState>
     <rosDebugLevel>na</rosDebugLevel>
     <wheelAcceleration>0</wheelAcceleration>
     <wheelTorque>5</wheelTorque>
     <odometrySource>world</odometrySource>
     <publishTf>1</publishTf>
    </plugin>
</gazebo>
  <!-- hokuyo -->
  <gazebo reference="laser_sensor">
    <sensor type="ray" name="head_hokuyo_sensor">
      <pose>0 0 0 0 0 0</pose>
      <visualize>false</visualize>
      <update_rate>20</update_rate>
      <ray>
        <scan>
          <horizontal>
            <samples>720</samples>
            <resolution>1</resolution>
            <min_angle>-1.570796</min_angle>
            <max_angle>1.570796</max_angle>
          </horizontal>
        </scan>
        <range>
          <min>0.10</min>
          <max>10.0</max>
          <resolution>0.01</resolution>
        </range>
        <noise>
          <type>gaussian</type>
          <mean>0.0</mean>
          <stddev>0.01</stddev>
        </noise>
      </ray>
      <plugin name="gazebo_ros_head_hokuyo_controller" filename="libgazebo_ros_laser.so">
        <topicName>/robot/laser/scan</topicName>
        <frameName>laser_sensor</frameName>
      </plugin>
    </sensor>
  </gazebo>
</robot>